Workbook

Sheet RSVPs - July 23
A1: name | B1: first_name | C1: last_name | D1: email | E1: Job Title | F1: Company | G1: Type of Company | H1: Email | I1: Telegram | J1: What's your LinkedIn ? | K1: Kindly provide the name of the person who invited you to this event
A2: Asi Burak | D2: aburak@tiltingpoint.com | E2: CBO | F2: Tilting Point | G2: Games | H2: aburak@tiltingpoint.com | J2: https://www.linkedin.com/in/asiburak/ | K2: Marina Espin
A3: Alex Crawford | B3: Alex | C3: Crawford | D3: alex.crawford@immutable.com | E3: Enterprise BDM | F3: Immutable | G3: Blockchain | H3: alex.crawford@immutable.com | I3: @alex_crawf | J3: https://www.linkedin.com/in/alexcrawfordau/ | K3: Sergio / Kamil
A4: Anna Kuzmenko | B4: Anna | C4: Kuzmenko | D4: anna.kuzmenko@immutable.com | E4: BD Manager APAC | F4: Immutable | G4: Games | H4: anna.kuzmenko@immutable.com | I4: immutanna | J4: https://linkedin.com/in/anna-kuzmenko | K4: Immutable team
A5: Antonio Guaranys | D5: antonio.guaranys@hermitcrabstudio.com | E5: Business Developer | F5: Hermit Crab | G5: Game Studio | H5: antonio.guaranys@hermitcrabstudio.com | J5: www.linkedin.com/in/antonioguaranys | K5: Trapper
A6: Ataberk Ates | B6: Ataberk | C6: Ates | D6: ataberk@ataberkates.com | E6: Lead Designer | F6: Climax Studios | G6: Game Studio | H6: ataberk@ataberkates.com | J6: https://www.linkedin.com/in/ataberkates/ | K6: -
A7: Polygon Labs | B7: Blake | C7: Payne | D7: bpayne@polygon.technology | E7: Manager | F7: Polygon | G7: Infrastructure | H7: bpayne@polygon.technology | J7: https://linkedin.com/in/blakefpayne | K7: Max
A8: Bret Curan | B8: Bret | C8: Curan | D8: bret@lightningforge.games | E8: Chief Product Officer / Co-founder | F8: Lightning Forge Games | G8: AI, Game Studio | H8: bret@lightningforge.games | I8: @BusinessCatAU | J8: https://linkedin.com/in/bret-curan-092b82256 | K8: Max Kaufman
A9: Caio Filizola | B9: Caio | C9: Filizola | D9: caiofilizola@cyanheartstudio.com | E9: CEO | F9: Cyan Heart Studio | G9: Games | H9: caiofilizola@cyanheartstudio.com | J9: https://www.linkedin.com/in/caio-filizola/ | K9: N/A
A10: chris castagnetto | B10: Chris | C10: Castagnetto | D10: ccas121@gmail.com | E10: Business Development | F10: TikTok | G10: Others | H10: ccas121@gmail.com | J10: https://www.linkedin.com/in/ccastagnetto/ | K10: web list
A11: Cecilia | D11: cecilia.fadul@kwalee.com | E11: Head of AdMonetisation | F11: Kwalee | G11: Games | H11: cecilia.fadul@kwalee.com | J11: https://www.linkedin.com/in/ceciliafadul/ | K11: slack
A12: Romain Schneider | B12: Romain | C12: Schneider | D12: ceo@spectarium.games | E12: CEO and Founder | F12: Spectarium Games | G12: Games | H12: Ceo@spectarium.games | J12: linkedin.com/in/rdgs15 | K12: Sam, WolvesDAO
A13: Chris Keeling | D13: chris@marsgames.com | E13: CEO | F13: Mars Games | G13: Games | H13: chris@marsgames.com | J13: https://www.linkedin.com/in/chriskeeling/ | K13: Mattie Fairchild
A14: Ciaran Daly | D14: ciaran.daly@twistedworks.com | E14: Director | F14: Twisted Works | G14: Games, Media | H14: ciaran.daly@twistedworks.com | J14: https://www.linkedin.com/in/ciarandaly/ | K14: N/A
A15: David Boileau | B15: David | C15: Boileau | D15: dave.boileau@gamebreaking.com | E15: Senior Engineering Manager | F15: Gamebreaking Studios | G15: Game Studio | H15: dave.boileau@gamebreaking.com | J15: https://www.linkedin.com/in/davidboileau/ | K15: Grace Zhou
A16: Diego Beltrame | B16: Diego | C16: Beltrame | D16: diego.beltrame@unity3d.com | E16: Sr Client Partner | F16: Unity Multiplay | G16: Infrastructure | H16: diego.beltrame@unity3d.com | J16: https://www.linkedin.com/in/beltramediego/ | K16: working with Web3 customers
A17: Elena Provine | B17: Elena | C17: Provine | D17: elena@equitywestadvisors.com | E17: Venture Partner | F17: Griffin Gaming | G17: VC | H17: elena@equitywestadvisors.com | I17: lena_provine | J17: https://www.linkedin.com/in/elenaprovine/ | K17: Greg Labuz
A18: flavia | B18: Flavia | D18: flavia.luz@webcore.com.br | E18: Operations | F18: Webcore Games | G18: Games | H18: flavia.luz@webcore.com.br | I18: 5511992077151 | J18: https://www.linkedin.com/in/flavialuz/ | K18: Grace Zhou
A19: Fred @ Funfair Ventures | B19: Fred | D19: frederico.kessler@funfair.io | E19: Partner | F19: Funfair ventures | G19: VC | H19: Frederico.kessler@funfair.io | I19: Fr3dsk | J19: https://linkedin.com/in/fr3dk | K19: Found it on luma
A20: GaspodeWD // Felix | B20: Felix | C20: Bracher | D20: gaspodewd@whatsyourgam3.com | E20: CSO // Head Of Marketing | F20: FDF // G3 | G20: Media | H20: gaspodewd@whatsyourgam3.com | J20: https://www.linkedin.com/in/felix-bracher/ | K20: Big Dog Max
A21: Georg Broxtermann | B21: Georg | C21: Broxtermann | D21: georg@gameinfluencer.com | E21: CEO | F21: GameInfluencer.com | G21: Media | H21: georg@gameinfluencer.com | J21: https://linkedin.com/in/broxtermann | K21: Sergio Varona Bustillo
A22: Grace Zhou | B22: Grace | C22: Zhou | D22: gracemin.zhou@gmail.com | E22: Director of Corp Dev | F22: Scopely | G22: Games | H22: grace.zhou@scopely.com | J22: https://linkedin.com/in/graceminzhou | K22: Polygon
A23: Gunjan Sharman | B23: Gunjan | C23: Sharman | D23: gunjan@beamable.com | E23: VP of Product | F23: Beamable | G23: Infrastructure | H23: gunjan@beamable.com | I23: i_gsharman | J23: https://linkedin.com/in/gsharman | K23: Max Kauffman
A24: Haye Anderson | B24: Haye | C24: Anderson | D24: haye.anderson@ubisoft.com | E24: Brand Director | F24: Ubisoft | G24: Game Studio | H24: Haye.anderson@ubisoft.com | J24: https://www.linkedin.com/in/andersonhayley/ | K24: Alex Brodsky
A25: Marcus Krautwurst | B25: Marcus | C25: Krautwurst | D25: hello@monster-puppet.com | E25: CEO | F25: Monster Puppet Corporation | G25: Games | H25: hello@monster-puppet.com | J25: https://www.linkedin.com/in/mkrautwurst?utm_source=share&utm_campaign=share_via&utm_content=profile&utm_medium=ios_app | K25: Hind
A26: Jan Roessner | B26: Jan | C26: Roessner | D26: jan@oneearthrising.com | E26: CEO | F26: One Earth Rising | G26: Infrastructure | H26: jan@oneearthrising.com | I26: @janroessner | J26: https://linkedin.com/in/janroessner | K26: Max Kaufman
A27: Joachim Rittfeldt Hofvenschiöld | B27: Joachim | C27: Rittfeldt Hofvenschiöld | D27: joachim@spectarium.games | E27: BD / Investor | F27: Spectarium Games / uBIT.vc | G27: Games, VC | H27: Joachim@ubit.vc | I27: Hofvenschiold | J27: Linkedin.com/in/hofven | K27: Sam, WolvesDAO
A28: John Bergman | D28: john@guildsoftware.com | E28: CEO | F28: Guild Software | G28: Game Studio, Game Publisher | H28: john@guildsoftware.com | I28: @JohnBergman | J28: linkedin.com/in/incarnate | K28: Grace Zhou's secret telegram thing. We have a live MMORPG with substantial users, considering possible blockchain partners.
A29: Justin Edwards | B29: Justin | C29: Edwards | D29: justin@twintec.io | E29: CPO | F29: WARP | G29: Game Publisher, Infrastructure, Blockchain | H29: Justin@twintec.io | I29: Juzzy007 | J29: https://www.linkedin.com/in/justin-edwards-876a193/ | K29: Matthew Buxton
A30: Kate Edwards | D30: kate@geogrify.com | E30: CEO / CXO & Cofounder | F30: Geogrify / SetJetters | G30: Others | H30: kate@geogrify.com | J30: https://www.linkedin.com/in/geogrify/ | K30: Hind Toufga
A31: Keith Flynn | B31: Keith | C31: Flynn | D31: keith.flynn@finoa.io | E31: Sr. Sales / Partnerships Manager | F31: Finoa | G31: Exchange, AI, Infrastructure | H31: keith.flynn@finoa.io | I31: @F_Keith | J31: https://www.linkedin.com/in/keith-flynn-/ | K31: Max via Jeremy Parris & Sonny Tsiopani
A32: Konrad Adamczewski | D32: konrad.adamczewski@11bitstudios.com | E32: Senior PR Manager | F32: 11 bit studios | G32: Game Publisher, Game Studio | H32: konrad.adamczewski@11bitstudios.com | J32: www.linkedin.com/in/konrad-adamczewski-292a26141 | K32: I just got a link from the list of events, honestly, so no direct person, unfortunately.
A33: Kristian | B33: Kristian | C33: Kolvek | D33: kristian@1minus1.com | E33: BD Manager at 1minus1 & BD Games Voice on Linkedin | F33: 1minus1 | G33: Others | H33: kristian@1minus1.com | J33: https://www.linkedin.com/in/kristiankolvek/ | K33: none
A34: Kevin Rubio | B34: Kevin | C34: Rubio | D34: krubio@tiltingpoint.com | E34: Director, Business Development | F34: Tilting Point | G34: Games | H34: krubio@tiltingpoint.com | J34: https://www.linkedin.com/in/kevin-rubio-ramirez/ | K34: Marina
A35: Krystian Jaroszynski | B35: Krystian | C35: Jaroszynski | D35: krystian@heroic.gg | E35: Chief commercial officer | F35: Heroic AS | G35: Others, Games | H35: krystian@heroic.gg | J35: www.linkedin.com/in/krystian-jaroszynski-80949437 | K35: Grace Zhou
A36: Kamil Zielinski | B36: Kamil | C36: Zielinski | D36: kzielinski@polygon.technology | E36: BD, Gaming | F36: Polygon Labs | G36: Blockchain, Games, Defi, Infrastructure | H36: kzielinski@polygon.technology | J36: www.linkedin.com/in/kzielinski94/ | K36: Sergio Varona, Max Kaufman, Blake Fuller
A37: Lisa-Maria Wittmann | B37: Lisa-Maria | C37: Wittmann | D37: lisa-maria.wittmann@ubisoft.com | E37: International Product Manager | F37: Ubisoft Mainz | G37: Game Studio | H37: lisa-maria.wittmann@ubisoft.com | J37: https://www.linkedin.com/in/lisamariawittmann/ | K37: Haye Anderson (Brand Director for Anno at Ubisoft Mainz)
A38: Marina | D38: marina@tiltingpoint.com | E38: VP of BD | F38: Tilting Point | G38: Games | H38: marina@tiltingpoint.com | J38: mespinfarran | K38: Sergio
A39: Martin Cao | B39: Martin | C39: Cao | D39: marto@martocao.com | E39: Partner | F39: Martocao | G39: Others | H39: marto@martocao.com | J39: https://www.linkedin.com/in/martincao/ | K39: .
A40: Marty Burgess | B40: Marty | C40: Burgess | D40: marty@lightningforge.games | E40: CEO | F40: Lightning Forge Games | G40: Game Studio | H40: marty@lightningforge.games | I40: @alcatrazzalz | J40: https://linkedin.com/in/marty-burgess | K40: Jas
...

Sheet RSVPs - July 30
A1: name | B1: first_name | C1: last_name | D1: email | E1: approval_status | F1: Job Title | G1: Company | H1: Type of Company | I1: Email | J1: Telegram | K1: What's your LinkedIn ? | L1: Kindly provide the name of the person who invited you to this event
A2: Aria Esrafilian | B2: Aria | C2: Esrafilian | D2: aria@troverse.io | E2: approved | F2: Founder | G2: Troverse (GameFi x GenAI | x.com/PlayTroverse) | H2: AI, Blockchain, Game Studio | I2: Aria@playtroverse.com | J2: @ariaesrafilian | K2: https://linkedin.com/in/ariaesrafilian | L2: GameFi project building on Polygon
A3: Berker Siino | B3: Berker | C3: Siino | D3: berkersiino@outlook.com | E3: approved | F3: Art Director | G3: MonsterPuppet | H3: Game Studio | I3: berker@monster-puppet.com | K3: https://www.linkedin.com/in/berkersiino/ | L3: Marcus
A4: Jeremy Parris | B4: Jeremy | C4: Parris | D4: jeremy@kingriver.co | E4: approved | F4: ventures/consulting | G4: King River Capital | H4: VC, Others | I4: jeremy@kingriver.co | J4: jeremystormsky | K4: https://www.linkedin.com/in/jeremy-parris-b242a4211/ | L4: know jon raddoff and a lot of the wolves
A5: Tommaso Jakob | B5: Tommaso | C5: Jakob | D5: tommaso.jakob@ubisoft.com | E5: approved | F5: Project Coordinator - ANNO Brand | G5: Ubisoft Mainz | H5: Game Studio | I5: tommaso.jakob@ubisoft.com | K5: https://www.linkedin.com/in/tommasojakob/ | L5: Haye Anderson
A6: Kristian Metzger | D6: kristian@stratosphere-games.com | E6: approved | F6: CEO | G6: Stratosphere Games GmbH | H6: Game Studio | I6: kristian@stratosphere-games.com | J6: @Khorneslayer24 | K6: https://linkedin.com/in/kristianmetzger | L6: Max Kaufman
A7: Tim Loosen | B7: Tim | C7: Loosen | D7: tim@lussa.io | E7: approved | F7: CBO | G7: Lussa | H7: Infrastructure | I7: Info@lussa.io | J7: @Powerlauch | K7: https://www.linkedin.com/in/tim-loo?utm_source=share&utm_campaign=share_via&utm_content=profile&utm_medium=android_app | L7: Jon Radoff
A8: Zlatko Stjepanović | B8: Zlatko | C8: Stjepanović | D8: zlatko@lussa.io | E8: approved | F8: CEO | G8: Lussa | H8: Infrastructure | I8: zlatko@lussa.io | J8: @zlatko369 | K8: https://www.linkedin.com/in/zlatko-z?utm_source=share&utm_campaign=share_via&utm_content=profile&utm_medium=android_app | L8: Jon Radoff
A9: Niels de Ruiter | B9: Niels | C9: de Ruiter | D9: hello@nielsderuiter.com | E9: approved | F9: Investor | G9: notneils | H9: VC | I9: hello@nielsderuiter.com | J9: noosoods | K9: https://www.linkedin.com/in/nielsderuiter1/ | L9: Max Kaufman (web3 frens group)
A10: MinChi Park | B10: Minchi | C10: Park | D10: park.minchi@gmail.com | E10: approved | F10: Head of Ecosystem | G10: HyperPlay | H10: Infrastructure, Blockchain | I10: minchi@hyperplay.xyz | K10: https://linkedin.com/in/minchipark | L10: Max
A11: Sydney Sharp | B11: Sydney | C11: Sharp | D11: ssharp@3thix.com | E11: approved | F11: Bd | G11: 3thix | H11: Blockchain, Infrastructure, Wallet | I11: Ssharp@3thix.com | J11: Sydneysharp | K11: https://www.linkedin.com/in/sydney--sharp | L11: Max Kaufman
A12: TIMOTHY R TELLO | B12: Timothy | C12: Tello | D12: ttello@3thix.com | E12: approved | F12: CEO | G12: 3thix | H12: Blockchain, Wallet, Infrastructure | I12: Ttello@3thix.com | J12: Tellotimothy | K12: https://www.linkedin.com/in/timothytello | L12: Max Kaufman
A13: Sebastien BORGET | B13: Sebastien | C13: Borget | D13: seb@sandbox.game | E13: approved | F13: Co-Founder | G13: The Sandbox | H13: Blockchain, Game Publisher | I13: seb@sandbox.game | J13: sebastienborget | K13: https://www.linkedin.com/in/borgetsebastien | L13: Max Kaufman
A14: Thomas Rössig | B14: Thomas | C14: Rössig | D14: thomas@roessig.biz | E14: approved | F14: Founder / Fractional CEO | G14: Game Founder Coach / Playing Mantis | H14: Game Studio | I14: thomas@roessig.biz | K14: https://www.linkedin.com/in/thomasroessig/ | L14: Not invited by someone, I used to run a studio in the web3 space.
A15: Robin Squire | B15: Robin | C15: Squire | D15: robin@blackbloxk.io | E15: approved | F15: CEO | G15: Black Block | H15: Game Studio, Infrastructure | I15: robin@blackblock.io | K15: https://www.linkedin.com/in/robin-squire | L15: Max Kaufman
A16: Anton Umnov | B16: Anton | C16: Umnov | D16: anton@helika.io | E16: approved | F16: Founder and CEO | G16: Helika | H16: Infrastructure, Game Publisher | I16: Anton@helika.io | K16: https://linkedin.com/in/anton-umnov | L16: Max
A17: Nahir | B17: Nahir | D17: mizuchin12@gmail.com | E17: approved | F17: CEO | G17: Dreams of Heaven Games | H17: Game Studio | I17: Mizuchin12@gmail.com | K17: https://linkedin.com/in/nahir-fajardo | L17: None
A18: Nate Dykstra | B18: Nate | C18: Dykstra | D18: nate.dykstra@mattel.com | E18: approved | F18: Business Development, Licensing | G18: Mattel | H18: Game Publisher | I18: nate.dykstra@mattel.com | K18: https://www.linkedin.com/in/natedykstra/ | L18: Giancarlo Rios
A19: Alex Tarrand | D19: alex@styngr.com | E19: approved | F19: COO | G19: STYNGR | H19: Media | I19: alex@styngr.com | J19: @alextarrand | K19: https://www.linkedin.com/in/alextarrand/ | L19: Grace
A20: Assad Dar | D20: assad.dar@moongaming.com | E20: approved | F20: Founder & CVO | G20: Medieval Empires | H20: Game Studio | I20: Assad.dar@gmail.com | J20: @assad_dar | K20: LinkedIn.com/in/assaddar | L20: Our $MEE token is on Polygon
A21: Rufus Kubica | D21: rufus.kubica@11bitstudios.com | E21: approved | F21: External Development Director | G21: 11 bit studios | H21: Game Publisher, Game Studio | I21: rufus.kubica@11bitstudios.com | K21: https://www.linkedin.com/in/rufus-kubica-9482b7a5/ | L21: Got the invite from our PR Team
A22: Oliver Löffler | B22: Oliver | C22: Löffler | D22: oliver@voya.games | E22: approved | F22: CEO | G22: VOYA Games | H22: Game Studio, Game Publisher | I22: oliver@voya.games | K22: https://www.linkedin.com/in/oliverloeffler/ | L22: Sai
A23: Luai Mahjneh | D23: luai.mahjneh@fennicagaming.com | E23: approved | F23: SVP | G23: Fennica Gaming | H23: Game Publisher | I23: luai.mahjneh@fennicagaming.com | K23: https://www.linkedin.com/in/luaimahjneh/ | L23: Tom Jaatinen
A24: Baptiste Granet | B24: Baptiste | C24: Granet | D24: baptiste.granet@immutable.com | E24: approved | F24: BD, EMEA Manager | G24: Immutable | H24: Blockchain | I24: baptiste.granet@immutable.com | J24: baptistegrnt | K24: https://linkedin.com/in/baptiste-granet | L24: No invite, but working with Sergio and Kamil on a regular basis
A25: Rana Rahman | B25: Rana | C25: Rahman | D25: rana@raptorpr.com | E25: approved | F25: CEO & Founder | G25: Raptor PR | H25: Media | I25: Rana@raptorpr.com | J25: @ranaraptor | K25: https://linkedin.com/in/ranaraptor | L25: Max Kaufman
A26: Joshua Callaghan | B26: Joshua | C26: Callaghan | D26: joshua@raptorpr.com | E26: approved | F26: Junior Account Manager | G26: Raptor PR | H26: Others | I26: joshua@raptorpr.com | K26: https://www.linkedin.com/in/joshua-callaghan/ | L26: Max Kaufman
A27: Mike Sanders | B27: Mike | C27: Sanders | D27: msanders@punyhuman.com | E27: approved | F27: Chief Development Officer | G27: Carbonated | H27: Game Studio | I27: msanders@punyhuman.com | J27: @urinalcake | K27: https://www.linkedin.com/in/mikerobyte/ | L27: Grace Zhou
A28: Dustin Brower | B28: Dustin | C28: Brower | D28: dustin@blueravenla.com | E28: approved | F28: Head of Brand Partnerships | G28: Blue Raven | H28: Others | I28: dustin@blueravenla.com | K28: https://www.linkedin.com/in/dustinbrower/ | L28: Grace Zhou
A29: Johnny Chua | B29: Johnny | C29: Chua | D29: johnny@lightningforge.games | E29: approved | F29: CCO | G29: Lightning Forge Games | H29: Game Studio, Blockchain | I29: johnny@lightningforge.games | J29: @Hit_Box_01 | K29: https://linkedin.com/in/jonathanjchua | L29: Max Kaufman
A30: Sean Shin | B30: Sean | C30: Shin | D30: seanshin@com2us.com | E30: approved | F30: Global BD Lead | G30: Com2uS Platform | H30: Game Studio | I30: seanshin@com2us.com | K30: https://www.linkedin.com/in/seonhoshin/ | L30: -
A31: Sky | B31: Sky | D31: sky@wolvesdao.io | E31: approved | F31: CTO | G31: Woof labs | H31: Others | I31: sky@wolvesdao.io | K31: https://www.linkedin.com/in/jonathan-bruenderman-4ba5151b/ | L31: Payton Kaleiwahea
A32: Serhat MARASLIGIL | B32: Serhat | C32: Marasligil | D32: smar@sequence.xyz | E32: approved | F32: Senior Producer | G32: Sequence | H32: Blockchain, Infrastructure, Wallet | I32: Smar@sequence.xyz | J32: Themarasligil | K32: https://www.linkedin.com/in/serhatmarasligil?utm_source=share&utm_campaign=share_via&utm_content=profile | L32: Max Kaufman
A33: Brian McWilliams | D33: brian@wildblueberrygames.com | E33: approved | F33: CEO | G33: Wild Blueberry Games | H33: Game Studio | I33: brian@wildblueberrygames.com | J33: @BrianMcWilliams | K33: https://www.linkedin.com/in/brian-mcwilliams-b68b63b8/ | L33: Michael Sanders shared the event with me
A34: Saad Zaeem | B34: Saad | C34: Zaeem | D34: saad@revolvinggames.com | E34: approved | F34: CEO | G34: Revolving Games | H34: Game Publisher | I34: saad@revolvinggames.com | K34: https://linkedin.com/in/saadzaeem | L34: Shreyansh
A35: Eujin OH | B35: Eujin | C35: Oh | D35: eujin@com2us.com | E35: approved | F35: Marketing Manager | G35: Com2us Platform | H35: Game Publisher, Game Studio, Infrastructure | I35: eujin@gmail.com | K35: https://www.linkedin.com/in/eujinoh/ | L35: Sunho Shin
A36: Clementine AH-GON | B36: Clementine | C36: Ah-Gon | D36: clementine.ah-hon@ubisoft.com | E36: approved | F36: Junior International Product Manager | G36: Ubisoft Mainz | H36: Game Studio | I36: clementine.ah-hon@ubisoft.com | K36: https://www.linkedin.com/in/clementine-ah-hon/ | L36: Haye Anderson
A37: David An | B37: David | C37: An | D37: david@dracoon.ventures | E37: approved | F37: Managing Partner | G37: Dracoon Ventures | H37: VC, Blockchain | I37: david@dracoon.ventures | J37: davidkendo | K37: https://linkedin.com/in/davidan | L37: BGA
A38: Mel | B38: Mel | C38: Dow | D38: melanie@blockchaingamealliance.net | E38: approved | F38: Comms and BD | G38: Blockchain Game Alliance | H38: Blockchain | I38: Melanie@blockchaingamealliance.net | K38: https://linkedin.com/in/melanie-dow | L38: Sergio
A39: Gabriela Siemienkowicz | B39: Gabriela | C39: Siemienkowicz | D39: gabriela.siemienkowicz@11bitstudios.com | E39: approved | F39: Communications Lead | G39: 11 Bit Studios | H39: Game Publisher, Game Studio | I39: gabriela.siemienkowicz@11bitstudios.com | J39: Poland | K39: https://www.linkedin.com/in/gabriela-siemienkowicz/ | L39: Jason Ying
A40: Laurens | B40: Laurens | C40: Lauwverse | D40: lamastijgen@gmail.com | E40: approved | F40: CPO | G40: WolvesDAO | H40: Media | I40: Lauw@wolvesdao.io | K40: http://linkedin.com/in/laurensverweij | L40: Wolvesdao
...

Sheet RSVPs - Aug 6
A1: name | B1: first_name | C1: last_name | D1: email | E1: approval_status | F1: Job Title | G1: Company | H1: Type of Company | I1: Email | J1: Telegram | K1: What's your LinkedIn ? | L1: Kindly provide the name of the person who invited you to this event
A2: Jakub Vambersky | B2: Jakub | C2: Vambersky | D2: jvambersky@madfingergames.com | E2: approved | F2: Lead Community Manager | G2: MADFINGER Games | H2: Game Studio | I2: jvambersky@madfingergames.com | K2: https://www.linkedin.com/in/jakub-vambersky-%F0%9F%94%9C-gamescom-99179312b/ | L2: Dominik Jícha
A3: Oliver Warren | B3: Oliver | C3: Warren | D3: ollie.warren@unity3d.com | E3: approved | F3: Senior Solution Architect | G3: Unity | H3: Infrastructure | I3: ollie.warren@unity3d.com | K3: https://www.linkedin.com/in/ollie-warren-080306143/ | L3: Diego Beltrame
A4: Philippe Robert | B4: Philippe | C4: Robert | D4: philippe@tarokai.com | E4: approved | F4: CEO | G4: Tarokai | H4: Game Studio | I4: philippe@tarokai.com | K4: https://www.linkedin.com/in/philippe-robert-peachfarmer/ | L4: Baptiste Granet
A5: Lucie Colin | B5: Lucie | C5: Colin | D5: contact@tarokai.com | E5: approved | F5: COO | G5: tarokai | H5: Game Studio | I5: contact@tarokai.com | K5: https://www.linkedin.com/in/luciecolinrobert/ | L5: Baptiste granet
A6: funza | B6: funza | D6: funza15@gmail.com | E6: approved | F6: Customer Suport | G6: MADFINGER games | H6: Game Studio | I6: funza15@gmail.com | K6: https://www.linkedin.com/in/jan-nechvatal/ | L6: Dominik Jicha
A7: Dominik Jícha | B7: Dominik | C7: Jícha | D7: djicha@madfingergames.com | E7: approved | F7: Marketing Director | G7: MADFINGER Games, a.s. | H7: Game Publisher, Game Studio | I7: djicha@madfingergames.com | K7: https://www.linkedin.com/in/dominikjicha/ | L7: Found myself
A8: Hannibal Soares | B8: Hannibal | C8: Soares | D8: hannibal@boomland.io | E8: approved | F8: CEO | G8: BoomLand | Web3 Game Publishing | H8: Game Publisher | I8: Hannibal@boomland.io | K8: https://linkedin.com/in/hannibalsoares | L8: Max Kaufman
A9: Vitalii Vashchuk | B9: Vitalii | C9: Vashchuk | D9: vitalii@vashchuk.org | E9: approved | F9: Vice President, Global Head of Gaming | G9: EPAM | H9: Infrastructure, AI | I9: vitalii_vashchuk@epam.com | J9: vit.vas1 | K9: https://linkedin.com/in/vashchukvitalii | L9: Grace Zhou or use Jon Radoff
A10: Jas Singh | B10: Jas | C10: Singh | D10: jas@lightningforge.games | E10: approved | F10: Head of Marketing | G10: Lightning Forge Games | H10: Game Studio | I10: jas@lightningforge.games | J10: brains_ct | K10: https://www.linkedin.com/in/jasvir-singh-06119b1b7/ | L10: Max Kaufman
A11: Long Chu | B11: Long | C11: Chu | D11: long@ggwp.com | E11: approved | F11: VP Ops | G11: GGWP | H11: AI | I11: long@ggwp.com | K11: https://www.linkedin.com/in/longchu88/ | L11: Joi Podgorny
A12: Kathleen Sherman | B12: Kathleen | C12: Sherman | D12: kathleen.sherman@lysto.io | E12: approved | F12: Senior Game Partnerships Manager at Lysto | G12: Lysto | H12: Others | I12: kathleen.sherman@lysto.io | K12: https://www.linkedin.com/in/kathleen-sherman/ | L12: n/a
A13: Travis Anderson | B13: Travis | C13: Anderson | D13: t.anderson@xsolla.com | E13: approved | F13: Head of Developer Partnerships | G13: Xsolla | H13: Infrastructure, Blockchain, Game Publisher, VC | I13: t.anderson@xsolla.com | K13: https://www.linkedin.com/in/travisandersonpro/ | L13: Sanket Shah
A14: Andrew Willson | B14: Andrew | C14: Willson | D14: andrew@makersfund.com | E14: approved | F14: General Partner | G14: Makers Fund | H14: VC | I14: andrew@makersfund.com | K14: https://linkedin.com/in/andrewjswillson | L14: Polygon team
A15: Sergei Vasiuk | B15: Sergei | C15: Vasiuk | D15: sergei@vasi.uk | E15: approved | F15: Product Director | G15: Wargaming | H15: Game Studio, Game Publisher | I15: sergei@vasi.uk | K15: https://www.linkedin.com/in/sergeivasjuk/ | L15: Grace Zhou
A16: JOI PODGORNY from GGWP | B16: Joi | C16: Podgorny | D16: joi@ggwp.com | E16: approved | F16: Marketing & Partnerships | G16: GGWP | H16: Infrastructure | I16: joi@ggwp.com | K16: https://linkedin.com/in/joipodgorny | L16: Event list
A17: Cvetan Rusimov | B17: Cvetan | C17: Rusimov | D17: rusimov@imperiaonline.org | E17: approved | F17: CEO | G17: Imperia Online JSC | H17: Game Studio, Game Publisher | I17: rusimov@imperiaonline.org | K17: https://www.linkedin.com/in/rusimov/ | L17: Erica
A18: Laurin Bylica | B18: Laurin | C18: Bylica | D18: lb@n8.capital | E18: approved | F18: Co-founder | G18: n8 Capital | H18: VC | I18: lb@n8.capital | J18: laurin_byl | K18: https://linkedin.com/in/laurin-bylica | L18: Tim
A19: DANIEL FERNANDEZ | B19: Daniel | C19: Fernandez | D19: daniel.fernandez@ninjugames.com | E19: approved | F19: CEO | G19: NINJU GAMES | H19: Game Studio, Blockchain | I19: gamescom@ninjugames.com | K19: https://www.linkedin.com/in/mutantdani/ | L19: Continuum World developers
A20: Antonio de la Torre | B20: Antonio | C20: de la Torre | D20: sasori@ninjugames.com | E20: approved | F20: CTO | G20: Ninju Games | H20: Game Studio | I20: sasori@ninjugames.com | K20: https://www.linkedin.com/in/sasori-olkof | L20: Ninju games is the developer of continuum world, based on polygon network
A21: Stan Fiedor | B21: Stan | C21: Fiedor | D21: stan@wemade.com | E21: approved | F21: GM Europe | G21: WEMADE | H21: Game Publisher, Blockchain | I21: Stan@wemade.com | J21: @stanfiedor | K21: https://www.linkedin.com/in/sfiedor?utm_source=share&utm_campaign=share_via&utm_content=profile&utm_medium=ios_app | L21: Jon
A22: Amy | B22: Amy | D22: amxwhite@twitch.tv | E22: approved | F22: communications director | G22: Twitch, Amazon | H22: Others | I22: amxwhite@twitch.tv | K22: https://www.linkedin.com/in/amy-white1/ | L22: Dan Clancy - Twitch CEO
A23: Behfar | B23: Behfar | C23: Iranmanesh | D23: behfar@chronogames.net | E23: approved | F23: CEO | G23: Chrono Games | H23: Game Studio, AI | I23: behfar@chronogames.net | J23: behfar | K23: https://linkedin.com/in/behfar-iranmanesh-3223a6154 | L23: Gaspode (felix)
A24: Cointelegraph | B24: Maria | C24: A Schaefer | D24: maria.a@cointelegraph.com | E24: approved | F24: Events Lead | G24: Cointelegraph, Maria A | H24: Media | I24: maria.a@cointelegraph.com | J24: MaryAbb | K24: https://linkedin.com/company/cointelegraph | L24: NA
A25: chris castagnetto | D25: chris.castagnetto@bytedance.com | E25: approved | F25: Business Development | G25: TikTok | H25: Others | I25: chris.castagnetto@bytedance.com | K25: https://www.linkedin.com/in/ccastagnetto/ | L25: web list
A26: Jongmoon Kim | B26: Jongmoon | C26: Kim | D26: jongmoonkim@com2us.com | E26: approved | F26: Senior Vice President | G26: Com2uS Platform | H26: Game Publisher | I26: jongmoonkim@com2us.com | K26: https://www.linkedin.com/in/jong-moon-k-32481979/ | L26: -
A27: Tyrus Taylor | B27: Tyrus | C27: Taylor | D27: tyrus.taylor@immutable.com | E27: approved | F27: Senior BD Manager | G27: Immutable | H27: Blockchain | I27: tyrus.taylor@immutable.com | K27: https://www.linkedin.com/in/tyrus-taylor-b18567121/ | L27: Web3 Frens TG / Payton
A28: Hajar Noreddine | B28: Hajar | C28: Noreddine | D28: hajar@zbdpay.com | E28: approved | F28: VP of Business Development | G28: ZBD | H28: Wallet, Blockchain | I28: hajar@zbdpay.com | K28: https://www.linkedin.com/in/hajar-noreddine/ | L28: N/A
A29: Matt Daly | B29: Matt | C29: Daly | D29: howdy@mattda.ly | E29: approved | F29: Founder | G29: Banana Foundry | H29: Blockchain, Game Studio | I29: Matt@chaincraft.games | J29: Bliargh | K29: https://linkedin.com/in/dalymatt | L29: Elena Provine
A30: Anton Vinogradov | D30: anton@samustai.com | E30: approved | F30: Director | G30: Samustai LTD | H30: Game Publisher, Game Studio | I30: anton@samustai.com | J30: @comrademozes | K30: https://www.linkedin.com/in/mimozes/ | L30: My colleagues from publishing chat offered to meet there
A31: shahar sosa | B31: Shahar | C31: Sosa | D31: sh.sosa@gmail.com | E31: approved | F31: Co founder | G31: Rabbit hole creations | H31: Game Studio | I31: sh.sosa@gmail.com | K31: https://www.linkedin.com/in/shahar-emanuel-sosa-72b5b71a6/ | L31: David
A32: Jin Y. Bae | B32: Jin | C32: Bae | D32: jin@opengamefoundation.org | E32: approved | F32: Executive Director | G32: Opengame Foundation(CROSS) & NEXUS(Dev Co) | H32: Blockchain | I32: jin@opengamafoundation.org | K32: https://www.linkedin.com/in/jin-yeongjin-bae-40b75515/ | L32: Sebastien (sangboxgame)
A33: Thomas Shim | B33: Thomas | C33: Shim | D33: tshim@to.nexus | E33: approved | F33: Head of Global Business | G33: NEXUS | H33: Blockchain, Others | I33: tshim@to.nexus | J33: @tshim15 | K33: https://www.linkedin.com/in/thomasshim | L33: Sebastien BORGET
A34: Daniel Wilén | D34: daniel.wilen@arcticgame.se | E34: approved | F34: Managing Director | G34: Arctic Game | H34: Others | I34: daniel.wilen@arcticgame.se | J34: Sverige | K34: https://www.linkedin.com/in/danielwilen/ | L34: Pontus Mahler
A35: Arne Peters | B35: Arne | C35: Peters | D35: arne@metaverseme.io | E35: approved | F35: Co-Founder | G35: MetaverseME | H35: Infrastructure, Game Publisher, Game Studio | I35: arne@metaverseme.io | K35: https://www.linkedin.com/in/arnepeters/ | L35: Max Kaufman
A36: SEOKJIN YONG | B36: Seokjin | C36: Yong | D36: seokinyong@com2us.com | E36: approved | F36: Hive SDK Solutions Archtect team, Assistant Manager | G36: Com2uS Platform Corp | H36: Game Publisher | I36: seokjinyong@com2us.com | K36: www.linkedin.com/in/ seokjinyong-b5a961378 | L36: David Mohr
A37: Robert Huynh | B37: Robert | C37: Huynh | D37: robert@reforgedlabs.com | E37: approved | F37: Co-Founder & CEO | G37: Reforged Labs | H37: AI | I37: robert@reforgedlabs.com | K37: https://linkedin.com/in/huynhrobert | L37: Mihailo
A38: Joanie Kraut | D38: joanie@getwigi.com | E38: approved | F38: CEO | G38: Women in Games International | H38: Others, Infrastructure | I38: Joanie@getwigi.com | K38: https://www.linkedin.com/in/joanie-kraut?utm_source=share&utm_campaign=share_via&utm_content=profile&utm_medium=ios_app | L38: Max Kaufman
A39: Höskuldur Sigurðarson | D39: hoskuldur@polarregiongames.com | E39: approved | F39: Founder/CEO | G39: Polar Region Games | H39: Game Studio | I39: hoskuldur@polarregiongames.com | K39: https://www.linkedin.com/in/hoskuldurs/ | L39: From list of Grace Zhou
A40: Arsen Chatalian | B40: Arsen | C40: Chatalian | D40: arsen@astrocat.co | E40: approved | F40: Chief Operating Officer | G40: Astro Cat | H40: Game Studio | I40: arsen@astrocat.co | K40: https://www.linkedin.com/in/chatalian/ | L40: I have been working with Beamable on Star Trek Timelines for the past 5 years (at TiltingPoint and CEO of High Ground). Thought it would be nice to meet the Beamable team in person.
...

Sheet RSVPs - Aug 13
A1: name | B1: first_name | C1: last_name | D1: email | E1: approval_status | F1: Job Title | G1: Company | H1: Type of Company | I1: Email | J1: Telegram | K1: What's your LinkedIn ? | L1: Kindly provide the name of the person who invited you to this event
A2: Jakub Vambersky | B2: Jakub | C2: Vambersky | D2: jvambersky@madfingergames.com | E2: approved | F2: Lead Community Manager | G2: MADFINGER Games | H2: Game Studio | I2: jvambersky@madfingergames.com | K2: https://www.linkedin.com/in/jakub-vambersky-%F0%9F%94%9C-gamescom-99179312b/ | L2: Dominik Jícha
A3: Mariano Rubinstein | B3: Mariano | C3: Rubinstein | D3: mr@suragaming.com | E3: approved | F3: CEO & Co-founder | G3: Sura Gaming | Sura Ventures | H3: Game Studio, Wallet, VC | I3: mr@suragaming.com | K3: https://linkedin.com/in/marianorubinstein | L3: Sergio Varona
A4: Rick Lagnese | B4: Rick | C4: Lagnese | D4: rlagnese@madfingergames.com | E4: approved | F4: PR Director | G4: MADFINGER Games | H4: Game Studio | I4: rlagnese@madfingergames.com | K4: https://www.linkedin.com/in/rick-lagnese/ | L4: Dominik Jicha
A5: jorge jimenez | B5: Jorge | C5: Jimenez | D5: jorge@thegamingstrategist.com | E5: approved | F5: CEO | G5: The Gaming Strategist | H5: Media | I5: jorge@thegamingstrategist.com | J5: thegamingstrategist | K5: https://linkedin.com/company/the-gaming-strategist | L5: payton
A6: Rob Esom | B6: Rob | C6: Esom | D6: rob@swiperight.gg | E6: approved | F6: Director, Games Publishing and Tech | G6: Swipe Right | H6: Game Publisher | I6: rob@swiperight.gg | K6: https://www.linkedin.com/in/robert-esom-8b1bb7120/ | L6: Amy White
A7: Alfredo Bárcena | B7: Alfredo | C7: Bárcena | D7: alfredobarcena@merso.io | E7: approved | F7: Head of EMEA | G7: Merso.io | H7: Others, Blockchain | I7: alfredobarcena@merso.io | J7: @alfredobarcena | K7: https://www.linkedin.com/in/alfredo-b%C3%A1rcena-guti%C3%A9rrez-de-ter%C3%A1n-%F0%9F%94%9C-gamescom-cologne-23a9b415/ | L7: Sergio Varona
A8: David Magnier | B8: David | C8: Magnier | D8: david.magnier@mrkite.io | E8: approved | F8: Head of BD & Growth | G8: Youmio / TODAY The Game | H8: AI, Game Studio | I8: david.magnier@mrkite.io | K8: https://linkedin.com/company/mrkite | L8: Michael O'Connor
A9: Kun Gao | B9: Kun | C9: Gao | D9: kun@forge.gg | E9: approved | F9: CEO | G9: Forge | H9: Infrastructure | I9: kun@forge.gg | K9: https://linkedin.com/in/kungao | L9: Polygon
A10: Gabriel Perez | B10: Gabriel | C10: Perez | D10: gabriel@forge.gg | E10: approved | F10: Head of BD and Partnership | G10: Forge.gg | H10: Others | I10: gabriel@forge.gg | J10: grperez | K10: https://www.linkedin.com/in/gabrielrperez/ | L10: Sergio
A11: Domenik Maier | B11: Domenik | C11: Maier | D11: dm@strayshot.game | E11: approved | F11: Ceo | G11: iBLOXX | H11: Game Studio | I11: Dm@strayshot.game | J11: iBloxx | K11: https://www.linkedin.com/in/domenik-maier-%F0%9F%94%9C-gamescom-a291ab130?utm_source=share&utm_campaign=share_via&utm_content=profile&utm_medium=ios_app | L11: Linkedin
A12: Robin Squire | B12: Robin | C12: Squire | D12: robin@blackblock.io | E12: approved | F12: CEO | G12: Black Block | H12: Game Studio, Infrastructure | I12: robin@blackblock.io | J12: @robinblackblock | K12: https://www.linkedin.com/in/robin-squire?utm_source=share&utm_campaign=share_via&utm_content=profile&utm_medium=ios_app | L12: Max Kaufman
A13: Paul Van Eijden | B13: Paul | C13: Van Eijden | D13: paul@cre8labs.io | E13: approved | F13: CTO | G13: CRE8 LABS | H13: Game Studio | I13: paul@cre8labs.io | K13: paulvaneijden | L13: Beamable
A14: Sylvain Loe-Mie | B14: Sylvain | C14: Loe-Mie | D14: sylvain.loe-mie@ubisoft.com | E14: approved | F14: Executive Producer | G14: Ubisoft | H14: Game Studio, Game Publisher | I14: Sylvain.loe-mie@ubisoft.com | K14: https://linkedin.com/in/sloemie | L14: Noone
A15: Doyi Kim | B15: Doyi | C15: Kim | D15: doyi@opengamefoundation.org | E15: approved | F15: Head of U.S. | G15: Opengame Foundation | H15: Blockchain, Game Publisher, Game Studio | I15: doyi@opengamefoundation.org | K15: https://www.linkedin.com/in/doyikim22/ | L15: Malcolm
A16: James Wing | B16: James | C16: Wing | D16: james.wing@mystenlabs.com | E16: approved | F16: Gaming Partnerships | G16: Mysten Labs | H16: Blockchain | I16: james.wing@mystenlabs.com | J16: stvrgeon | K16: https://www.linkedin.com/in/jamesmwing/ | L16: Ryan MacKeen
A17: Dan Bunting | B17: Dan | C17: Bunting | D17: dan@1amgaming.com | E17: approved | F17: Venture Partner | G17: 1AM Gaming | H17: VC | I17: dan@1amgaming.com | J17: 13109909709 | K17: https://linkedin.com/in/danbunting | L17: Grace Zhou event list
A18: Berube | C18: Berube | D18: berube@hellogiant.com | E18: approved | F18: Co-Founder | CCO | G18: Hello Giant | H18: Game Studio | I18: berube@hellogiant.com | K18: https://www.linkedin.com/in/jonathan-berube-avtr/ | L18: Grace Zhou event list
A19: Samuel j Steffanina | B19: Samuel | C19: Steffanina | D19: samsteffanina@gmail.com | E19: approved | F19: Chief Marketing Officer | G19: WolvesDAO / Remix | H19: Game Studio, Media | I19: samsteffanina@gmail.com | J19: samsteffanina1 | K19: linkedin.com/in/samsteffanina | L19: Payton Kalewahea
A20: Sarah Chafer | B20: Sarah | C20: Chafer | D20: s.chafer@xsolla.com | E20: approved | F20: Global Head of Sales, Xsolla Ads | G20: Xsolla | H20: Media | I20: s.chafer@xsolla.com | J20: United States | K20: https://www.linkedin.com/in/sarahprescottchafer/ | L20: Travis Anderson
A21: Lauren Baca | B21: Lauren | C21: Baca | D21: l.baca@xsolla.com | E21: approved | F21: VP of Marketing, Xsolla | G21: Xsolla | H21: Others | I21: l.baca@xsolla.com | K21: https://www.linkedin.com/in/laurenfrisciabaca/ | L21: Travis Anderson
A22: dub | B22: Andrew | C22: Wion | D22: dub@glittercloud.solutions | E22: approved | F22: Co-Founder | G22: Glitter Cloud Solutions | H22: Game Publisher | I22: dub@glittercloud.solutions | J22: uhhdub | K22: https://www.linkedin.com/in/andrew-dub-wion-064683b0/ | L22: Payton
A23: Oliver | B23: Oliver | C23: Maroney | D23: oliver.maroney@opensea.io | E23: approved | F23: Head of BD | G23: OpenSea | H23: Infrastructure | I23: Oliver.maroney@opensea.io | J23: @olivermaroney | K23: olivermaroney | L23: Payton
A24: Jacob Vandevelde | B24: Jacob | C24: Vandevelde | D24: jacob.vandevelde@sony.com | E24: approved | F24: Manager, Product Development | G24: SIE, PlayStation | H24: Others, Game Publisher, Game Studio | I24: jacob.vandevelde@sony.com | K24: https://www.linkedin.com/in/jacobvandevelde/ | L24: Sam Pottinger
A25: Si Lakos | B25: Si | C25: Lakos | D25: simon.lakos@mrkite.io | E25: approved | F25: VP Content | G25: Youmio | H25: AI | I25: Simon.lakos@mrkite.io | K25: https://linkedin.com/company/mrkite | L25: Peyton
A26: Sean Kauppinen | B26: Sean | C26: Kauppinen | D26: imseank@gmail.com | E26: approved | F26: Chief Strategy Officer | G26: Game industry LLC | H26: Game Studio | I26: imseank@gmail.com | J26: SeanWeb3 | K26: https://www.linkedin.com/in/seank/ | L26: Connor and Declan
A27: Ana | B27: Ana | C27: Touza Medina | D27: ana@onbeam.com | E27: approved | F27: PSM | G27: Beam | H27: Blockchain | I27: ana@onbeamc.om | J27: @AnaMaTM | K27: https://linkedin.com/in/am-tm | L27: Mike
A28: Andrea De Cunto | B28: Andrea | C28: De Cunto | D28: dek@molokstudios.com | E28: approved | F28: CEO | G28: Molok studios | H28: Others, Game Publisher | I28: dek@molokstudios.com | J28: 393914880943 | K28: https://www.linkedin.com/in/andreadecunto/ | L28: Max Behringer
A29: Jillian Mood | B29: Jillian | C29: Mood | D29: jillian.mood@gmail.com | E29: approved | F29: HR & Marketing | G29: Pomme | H29: Game Studio | I29: jillian@pommeconsultants.com | K29: https://www.linkedin.com/in/hrwonderwoman/ | L29: Jon
A30: Didier Mayda | B30: Didier | C30: Mayda | D30: didier.mayda@ubisoft.com | E30: approved | F30: Producer | G30: Ubisoft | H30: Game Studio, Game Publisher | I30: Didier.mayda@ubisoft.com | J30: @DragoncelloIM | K30: https://linkedin.com/in/didier-mayda-b6887415 | L30: Wolves
A31: Mark Tarrisse | B31: Mark | C31: Tarrisse | D31: mark.tarrisse@ubisoft.com | E31: approved | F31: Art director | G31: Ubisoft | H31: Game Publisher | I31: mark.tarrisse@ubisoft.com | K31: https://fr.linkedin.com/in/mark-tarrisse-8238761b | L31: wolves
A32: Brian Rohaly | D32: brian@alwaysgeekygames.com | E32: approved | F32: VP Marketing | G32: Voxies | H32: Game Studio | I32: brian@alwaysgeekygames.com | K32: https://www.linkedin.com/in/rohaly/ | L32: Sergio Varona
A33: Aaron Fletcher | D33: aaron.fletcher@sony.com | E33: approved | F33: Director | G33: PlayStation | H33: Game Publisher | I33: Aaron.fletcher@sony.com | K33: https://www.linkedin.com/in/aaron7?utm_source=share&utm_campaign=share_via&utm_content=profile&utm_medium=android_app | L33: Jacob Vandevelde
A34: Nikolaj Yatsyshyn | B34: Nikolaj | C34: Yatsyshyn | D34: nikolaj@kavagaming.com | E34: approved | F34: CTO | G34: Kava Gaming Studio | H34: Game Studio | I34: Nikolaj@kavagaming.com | K34: https://www.linkedin.com/in/nikolaj-yatsyshyn-12865920a/ | L34: Roman
A35: Abhir Das | D35: abhir@playsuper.club | E35: approved | F35: Founder | G35: PlaySuper Software Solutions Pvt. Ltd | H35: Infrastructure | I35: abhir@playsuper.club | J35: @iamabhir2709 | K35: https://www.linkedin.com/in/abhirdas/ | L35: Shreyansh
A36: Veronika Kotková | B36: Veronika | C36: Kotková | D36: vkotkova@madfingergames.com | E36: approved | F36: Community Manager | G36: MADFINGER Games | H36: Game Studio | I36: vkotkova@madfingergames.com | K36: https://www.linkedin.com/in/veronika-kotkova/ | L36: Dominik Jicha
A37: Yulia Bukareva | B37: Yulia | C37: Bukareva | D37: bukareva@playgama.com | E37: approved | F37: Head of Business Development | G37: Playgama.com | H37: Game Publisher | I37: bukareva@playgama.com | K37: https://www.linkedin.com/in/jbukareva/ | L37: spreadsheet with public events
A38: Valeria Svistunova | B38: Valeria | C38: Svistunova | D38: valeria.svistunova@playgama.com | E38: approved | F38: Head of Monetization | G38: Playgama.com | H38: Game Publisher | I38: valeria.svistunova@playgama.com | K38: https://www.linkedin.com/in/valeria-svistunova/ | L38: Julia
A39: Dmitry Kachmar | B39: Dmitry | C39: Kachmar | D39: monnaboter@gmail.com | E39: approved | F39: Founder | G39: Playgama.com | H39: Game Publisher | I39: monnaboter@gmail.com | J39: @dkachmar | K39: https://www.linkedin.com/in/dmitry-kachmar-84392725/ | L39: Yulia
A40: Jean-Philippe Saulnier | D40: jp@alwaysgeekygames.com | E40: approved | F40: COO | G40: AlwaysGeeky Games | H40: Game Studio, Blockchain | I40: jp@alwaysgeekygames.com | J40: @jpsaulnier | K40: jpsaulnier | L40: Sergio Varona
...

Sheet RSVPs - Aug 25
A1: name | B1: first_name | C1: last_name | D1: email | E1: approval_status | F1: Job Title | G1: Company | H1: Type of Company | I1: Email | J1: Telegram | K1: What's your LinkedIn ? | L1: Kindly provide the name of the person who invited you to this event
A2: Adam Straney | D2: adam@warped.games | E2: approved | F2: CEO | G2: Warped Games | H2: Game Studio | I2: Adam@warped.games | J2: Adam_warped | K2: Adamstraney | L2: Trapper
A3: Johannes Preis | B3: Johannes | C3: Preis | D3: johannes.preis@hator.gg | E3: approved | F3: Brand Director | G3: HATOR | H3: Others | I3: Johannes.preis@hator.gg | K3: https://www.linkedin.com/in/johannes-preis-144728104?utm_source=share&utm_campaign=share_via&utm_content=profile&utm_medium=android_app | L3: Tom Lemke
A4: Erik J. Caponi | B4: Erik | C4: J. Caponi | D4: erik.caponi@splashdamage.com | E4: approved | F4: Creative Director | G4: Splash Damage | H4: Game Studio | I4: erik.caponi@splashdamage.com | K4: https://www.linkedin.com/in/ecaponi | L4: Discovered on a list of events
A5: Joanna Rycyk | D5: joanna.rycyk@tatemultimedia.com | E5: approved | F5: Head of Production | G5: Tate Multimedia | H5: Game Publisher | I5: joanna.rycyk@tatemultimedia.com | K5: https://www.linkedin.com/in/joanna-rycyk-026593159?utm_source=share&utm_campaign=share_via&utm_content=profile&utm_medium=android_app | L5: Paweł Łaskarzewski
A6: Andy Dee | B6: Andy | C6: Dee | D6: acrossfy@gmail.com | E6: approved | F6: Founder, CEO | G6: Overtroll | H6: Game Studio | I6: Andy@overtroll.com | K6: https://www.linkedin.com/in/andrey-dyakov | L6: Who knows?)
A7: Turan Selvi | B7: Turan | C7: Selvi | D7: turan@clipster.gg | E7: approved | F7: Founder | G7: Clipster | H7: Media | I7: turan@clipster.gg | J7: saikyo | K7: https://www.linkedin.com/in/turan-selvi?utm_source=share&utm_campaign=share_via&utm_content=profile&utm_medium=ios_app | L7: Max Kaufmann
A8: Levi Romanov | B8: Levi | C8: Romanov | D8: levi.romanov@immutable.com | E8: approved | F8: Head of Americas | G8: Immutable | H8: Blockchain | I8: Levi.romanov@immutable.com | K8: https://www.linkedin.com/in/leviromanov | L8: Declan Steele
A9: Elsa Tung | B9: Elsa | C9: Tung | D9: elsa.tung@showheroes.com | E9: approved | F9: senior international BD manager | G9: ShowHeroes SE | H9: Media | I9: elsa.tung@showheroes.com | K9: https://www.linkedin.com/in/elsatung?utm_source=share&utm_campaign=share_via&utm_content=profile&utm_medium=ios_app | L9: tugrul
A10: Dilara Kececi | B10: Dilara | C10: Kececi | D10: dilara@lorienaccelerator.com | E10: approved | F10: Managing Partner | G10: Lorien Accelerator | H10: VC | I10: dilara@lorienaccelerator.com | K10: https://linkedin.com/in/dilarakececi | L10: Can Gunaslan
A11: Gonca Ertaner | B11: Gonca | C11: Ertaner | D11: gonca.ertaner@gmail.com | E11: approved | F11: CRM & Digital Innovation Manager | G11: Samsung Elwctronics GmbH | H11: AI, Others | I11: gonca.ertaner@gmail.com | J11: Deutschland | K11: https://www.linkedin.com/in/gonca-ertaner?utm_source=share&utm_campaign=share_via&utm_content=profile&utm_medium=android_app | L11: Laurin Bylica
A12: Yoav Sochen | B12: Yoav | C12: Sochen | D12: yoav@sochen.org | E12: approved | F12: Esports production Manager | G12: Freelance - former Riot Games | H12: Media | I12: yoav@sochen.org | K12: https://www.linkedin.com/in/yoav-sochen/ | L12: Krystian Jaroszynski
A13: Can Gunaslan | B13: Can | C13: Gunaslan | D13: can.gunaslan@gmail.com | E13: approved | F13: Senior Marketing Manager | G13: Google | H13: AI, Infrastructure | I13: cangunaslan@google.com | K13: https://www.linkedin.com/in/cgunaslan | L13: Bella
A14: Murphy | B14: Murphy | D14: murphy@imts.vip | E14: approved | F14: CEO | G14: Immortals Studios | H14: Game Studio | I14: murphy@imts.vip | K14: MurphyYang | L14: Kamil Zielinski
A15: Tom Lemke | B15: Tom | C15: Lemke | D15: tl@savagetech.gg | E15: approved | F15: Founder | G15: SavageTech | H15: iGaming | I15: Tl@savagetech.gg | K15: https://www.linkedin.com/in/tom-jang-lemke-33118499?utm_source=share&utm_campaign=share_via&utm_content=profile&utm_medium=android_app | L15: Max kaufmann
A16: Can Florian Ahegger | B16: Florian | C16: Ahegger | D16: ca@ca-agentur.com | E16: approved | F16: CEO | G16: ca agentur via Samsung | H16: Media, Others, Blockchain | I16: Ca@ca-agentur.com | J16: Uniquecol888 | K16: https://www.linkedin.com/in/can-florian-ahegger?utm_source=share&utm_campaign=share_via&utm_content=profile&utm_medium=ios_app | L16: Sandeep Nailwal
A17: Michael O'Connor | B17: Michael | C17: O'Connor | D17: michael.oconnor@mrkite.io | E17: approved | F17: Ceo | G17: Youmio | H17: AI | I17: Michael.oconnor@mrkite.io | K17: Mjoc9 | L17: Max, Jon
A18: Guga Zagonel | B18: Guga | C18: Zagonel | D18: guga@kreativitasstudio.com | E18: approved | F18: Ceo | G18: Kreativitas | H18: Game Studio | I18: Guga@kreativitasstudio.com | K18: https://linkedin.com/in/guga-zagonel | L18: Slack
A19: Gleb Skibitsky | B19: Gleb | C19: Skibitsky | D19: gleb@walletconnect.com | E19: approved | F19: Gaming Lead | G19: WalletConnect / Reown | H19: Infrastructure, Wallet | I19: gleb@walletconnect.com | K19: https://www.linkedin.com/in/skibitsky?utm_source=share&utm_campaign=share_via&utm_content=profile | L19: Olli from Voya games
A20: Oleg Suptelia | B20: Oleg | C20: Suptelia | D20: o.suptelia@4taleproduction.com | E20: approved | F20: CEO | G20: 4tale production | H20: Game Studio | I20: O.suptelia@4taleproduction.com | J20: @t4dxx | K20: https://www.linkedin.com/in/sugunwar | L20: Miomigames web3 developers
A21: keith cook | B21: Keith | C21: Cook | D21: keith@getspaceport.com | E21: approved | F21: Head of BD and Licensing | G21: Spaceport | H21: Others | I21: Keith@getspaceport.com | K21: Keithcook | L21: Craig Zevin
A22: Millie Yang | B22: Millie | C22: Yang | D22: millie@breeze.cash | E22: approved | F22: CEO | G22: Breeze | H22: Infrastructure | I22: Millie@breeze.cash | K22: LinkedIn.com/in/millieyang | L22: Jon radoff
A23: Philip Pan | B23: Philip | C23: Pan | D23: philip@breeze.cash | E23: approved | F23: Head of Payments | G23: Breeze | H23: iGaming, Infrastructure | I23: Philip@breeze.cash | K23: Linkedin.com/in/pfpan | L23: Serena
A24: Alvaro Gil | B24: Alvaro | C24: Gil | D24: alvaro.gil@tiktok.com | E24: approved | F24: BD Director | G24: Tiktok | H24: Media | I24: Alvaro.gil@tiktok.com | K24: Linkedin | L24: Slack
A25: Marcin | B25: Marcin | D25: marcin@revived.game | E25: approved | F25: Business Developer | G25: Revived Overworld | H25: Game Studio | I25: marcin@revived.game | K25: https://www.linkedin.com/in/marcin-oliwkowski-1665ab46?utm_source=share&utm_campaign=share_via&utm_content=profile&utm_medium=android_app | L25: Kamil Zielinski
A26: Chris Dawson | D26: chris@styngr.com | E26: approved | F26: CPO | G26: STYNGR | H26: Infrastructure, Others | I26: chris@styngr.com | J26: United Kingdom | K26: https://www.linkedin.com/in/chris-d-487b4321/ | L26: Alex Terrand
A27: Rudy Koch | B27: Rudy | C27: Koch | D27: rudy@joagames.io | E27: approved | F27: Co-founder | G27: JOA | H27: Infrastructure, Blockchain, AI, Game Studio | I27: rudy@joagames.io | K27: https://www.linkedin.com/in/rudykoch | L27: Shreyansh
A28: Matthew Conn | D28: matthew@vyersoft.com | E28: approved | F28: president | G28: Curse Free Studios/VYERSOFT | H28: Media | I28: Matthew@vyersoft.com | J28: Xxlsol | K28: mrmattconn | L28: Sergio
A29: Denis Matusovskiy | D29: denis.matusovskiy@streamscharts.com | E29: approved | F29: Partnerships Manager | G29: Streams Charts | H29: Infrastructure, Media | I29: denis.matusovskiy@streamscharts.com | K29: https://www.linkedin.com/in/denis-matusovskiy | L29: Max Kaufman
A30: Ana | B30: Ana | D30: anastasia@esm.one | E30: approved | F30: Partnerships & Sponsorships Manager | G30: Esports & Streams Charts | H30: Others | I30: anastasia@esm.one | K30: https://www.linkedin.com/in/anastasiia-kaidalova/ | L30: Max Kaufman
A31: Efe | B31: Efe | C31: Kucuk | D31: efekucuk@gmail.com | E31: approved | F31: Head of Gaming | G31: Tezos | H31: Blockchain | I31: efe.kucuk@trili.tech | J31: itsefekucuk | K31: https://linkedin.com/in/efekucuk | L31: None
A32: Sevilay Catakli | B32: Sevilay | C32: Catakli | D32: sevilay.catakli@icloud.com | E32: approved | F32: EA to CEO | G32: Epitome MMORPG: https://epitomegame.com | H32: Game Studio, AI | I32: sevilay.catakli@icloud.com | K32: https://www.linkedin.com/in/nickvalentino33 | L32: Nick
A33: Nicolas Valentino Smigielski | B33: Nicolas | C33: Valentino Smigielski | D33: nick@epitome.studio | E33: approved | F33: CEO | G33: Epitome MMORPG: https://epitomegame.com | H33: Game Studio, AI | I33: nick@epitome.studio | K33: https://linkedin.com/in/nickvalentino33 | L33: Mark
A34: Timur Tugambay | B34: Timur | C34: Tugambay | D34: timur@onetwoplay.games | E34: approved | F34: Co-founder | G34: OneTwoPlay | H34: Blockchain, Game Studio | I34: Timurtugambay@gmail.com | J34: @carboc | K34: https://www.linkedin.com/in/timur-tugambay?utm_source=share&utm_campaign=share_via&utm_content=profile&utm_medium=android_app | L34: Self registration
A35: Craig | B35: Craig | C35: Zevin | D35: craig@getspaceport.com | E35: approved | F35: COO | G35: Spaceport Technologies | H35: Blockchain, Infrastructure | I35: Craig@spaceport.xyz | J35: @whatupcraig | K35: https://linkedin.com/in/craig-zevin | L35: Angie
A36: Bella Flowers | B36: Bella | C36: Flowers | D36: bella@offbase.com | E36: approved | F36: Creative Marketing Manager | G36: Off Base | H36: Others, Media | I36: bella@offbase.com | J36: 17077411923 | K36: https://linkedin.com/in/bellaflowers | L36: n/a
A37: Dirk Schepens | B37: Dirk | C37: Schepens | D37: dirk@xspectar.com | E37: approved | F37: CEO | G37: MetaVentures SA - xSPECTAR | H37: iGaming, Game Studio | I37: dirk@xspectar.com | J37: @ds198200 | K37: None | L37: Kamil - Sergio
A38: Elyssa Grant | D38: egrlynt@justin.tv | E38: approved | F38: Senior Content Manager, Events | G38: Twitch | H38: Media | I38: egrlynt@twitch.tv | K38: Elyssagrant | L38: Amy White
A39: Toby Allen | B39: Toby | C39: Allen | D39: toby@jobsingames.com | E39: approved | F39: CEO | G39: StartupMill | H39: Game Studio | I39: Toby@startupmill.com | K39: LinkedIn.com/in/tobyallen | L39: Max
A40: Tabarak Paracha | D40: tabarak@tenjin.com | E40: approved | F40: Marketing Manager and BDM | G40: Tenjin | H40: Market Maker | I40: tabarak@tenjin.com | K40: https://www.linkedin.com/in/tabarak-paracha-%F0%9F%94%9C-gamescom-cologne-766b3a113/ | L40: Linkedin
...

Sheet Data - July 23
A1: Type of Company | B1: Total Count | D1: Total RSVP Approved | E1: Total Pending | F1: Total Sign Ups
A2: Games | B2: 22 | D2: 59 | E2: 64 | F2: =D2+E2 -> 123
A3: Game Studio | B3: 16
A4: Infrastructure | B4: 12
A5: Blockchain | B5: 8
A6: Game Publisher | B6: 8
A7: Others | B7: 7
A8: AI | B8: 6
A9: VC | B9: 4
A10: Media | B10: 3
A11: Exchange | B11: 1
A12: Wallet | B12: 1

Sheet Data - July 30
A1: Type of Company | B1: Total Count | D1: Total RSVP Approved | E1: Total Pending | F1: Total Sign Ups
A2: Game Studio | B2: 36 | D2: 123 | E2: 103 | F2: 228
A3: Infrastructure | B3: 29
A4: Game Publisher | B4: 23
A5: Games | B5: 22
A6: Blockchain | B6: 18
A7: Others | B7: 15
A8: AI | B8: 11
A9: Media | B9: 9
A10: VC | B10: 7
A11: Wallet | B11: 4
A12: Exchange | B12: 1
A13: iGaming | B13: 1

Sheet Data - Aug 6
A1: Type of Company | B1: Total Count | C1: % Increase | F1: Total RSVP Approved | G1: Total Pending | H1: Total Sign Ups | J1: Notable Companies
A2: Game Studio | B2: 65 | C2: =(B2-'Data - July 30'!B2)/'Data - July 30'!B2 -> 0.80555556 | F2: 190 | G2: 134 | H2: 324 | J2: Wargaming
A3: Infrastructure | B3: 41 | C3: =(B3-'Data - July 30'!B3)/'Data - July 30'!B3 -> 0.4137931 | E3: # increase WoW | F3: =F2-'Data - July 30'!D2 -> 67 | G3: =G2-'Data - July 30'!E2 -> 31 | H3: =H2-'Data - July 30'!F2 -> 96 | J3: Activision
A4: Game Publisher | B4: 40 | C4: =(B4-'Data - July 30'!B4)/'Data - July 30'!B4 -> 0.73913043 | E4: % increase WoW | F4: =(F2-'Data - July 30'!D2)/'Data - July 30'!D2 -> 0.54471545 | G4: =(G2-'Data - July 30'!E2)/'Data - July 30'!E2 -> 0.30097087 | H4: =(H2-'Data - July 30'!F2)/'Data - July 30'!F2 -> 0.42105263 | J4: Twitch
A5: Blockchain | B5: 31 | C5: =(B5-'Data - July 30'!B5)/'Data - July 30'!B5 -> 0.40909091 | J5: TikTok
A6: Others | B6: 26 | C6: =(B6-'Data - July 30'!B6)/'Data - July 30'!B6 -> 0.44444444 | J6: Discord
A7: Games | B7: 25 | C7: =(B7-'Data - July 30'!B7)/'Data - July 30'!B7 -> 0.66666667 | J7: Com2Us
A8: AI | B8: 17 | C8: =(B8-'Data - July 30'!B8)/'Data - July 30'!B8 -> 0.54545455 | J8: Team Liquid
A9: Media | B9: 15 | C9: =(B9-'Data - July 30'!B9)/'Data - July 30'!B9 -> 0.66666667 | J9: Tilting Point
A10: VC | B10: 11 | C10: =(B10-'Data - July 30'!B10)/'Data - July 30'!B10 -> 0.57142857 | J10: Gameloft
A11: Wallet | B11: 6 | C11: =(B11-'Data - July 30'!B11)/'Data - July 30'!B11 -> 0.5 | J11: Griffin Gaming
A12: iGaming | B12: 4 | C12: =(B12-'Data - July 30'!B12)/'Data - July 30'!B12 -> 3 | J12: Ubisoft
A13: Exchange | B13: 1 | C13: =(B13-'Data - July 30'!B13)/'Data - July 30'!B13 -> 0 | J13: Krafton
J14: Carry1st
J15: Wemade / Wemix
J16: Xsolla
J17: Reddit
J18: TapNation
J19: Paramount Global

Sheet Data - Aug 13
A1: Type of Company | B1: Total Count | C1: % Increase | F1: Total RSVP Approved | G1: Total Pending | H1: Total Sign Ups | J1: Notable Companies
A2: Game Studio | B2: 100 | C2: =(B2-'Data - Aug 6'!B2)/'Data - Aug 6'!B2 -> 0.53846154 | F2: 287 | G2: 148 | H2: 435 | J2: Wargaming
A3: Infrastructure | B3: 53 | C3: =(B3-'Data - Aug 6'!B3)/'Data - Aug 6'!B3 -> 0.29268293 | E3: # increase WoW | F3: =F2-'Data - Aug 6'!F2 -> 97 | G3: =G2-'Data - Aug 6'!G2 -> 14 | H3: =H2-'Data - Aug 6'!H2 -> 111 | J3: Activision
A4: Game Publisher | B4: 62 | C4: =(B4-'Data - Aug 6'!B4)/'Data - Aug 6'!B4 -> 0.55 | E4: % increase WoW | F4: =(F2-'Data - Aug 6'!F2)/'Data - Aug 6'!F2 -> 0.51052632 | G4: =(G2-'Data - Aug 6'!G2)/'Data - Aug 6'!G2 -> 0.10447761 | H4: =(H2-'Data - Aug 6'!H2)/'Data - Aug 6'!H2 -> 0.34259259 | J4: Twitch
A5: Blockchain | B5: 41 | C5: =(B5-'Data - Aug 6'!B5)/'Data - Aug 6'!B5 -> 0.32258065 | J5: TikTok
A6: Others | B6: 37 | C6: =(B6-'Data - Aug 6'!B6)/'Data - Aug 6'!B6 -> 0.42307692 | J6: Discord
A7: Games | B7: 31 | C7: =(B7-'Data - Aug 6'!B7)/'Data - Aug 6'!B7 -> 0.24 | J7: Com2Us
A8: AI | B8: 21 | C8: =(B8-'Data - Aug 6'!B8)/'Data - Aug 6'!B8 -> 0.23529412 | J8: Team Liquid
A9: Media | B9: 25 | C9: =(B9-'Data - Aug 6'!B9)/'Data - Aug 6'!B9 -> 0.66666667 | J9: Tilting Point
A10: VC | B10: 13 | C10: =(B10-'Data - Aug 6'!B10)/'Data - Aug 6'!B10 -> 0.18181818 | J10: Gameloft
A11: Wallet | B11: 7 | C11: =(B11-'Data - Aug 6'!B11)/'Data - Aug 6'!B11 -> 0.16666667 | J11: Griffin Gaming
A12: iGaming | B12: 7 | C12: =(B12-'Data - Aug 6'!B12)/'Data - Aug 6'!B12 -> 0.75 | J12: Ubisoft
A13: Exchange | B13: 1 | C13: =(B13-'Data - Aug 6'!B13)/'Data - Aug 6'!B13 -> 0 | J13: Krafton
J14: Carry1st
J15: Wemade / Wemix
J16: Xsolla
J17: Reddit
J18: TapNation
J19: Paramount Global
J20: Disney
J21: Microsoft
J22: Sony

Sheet Data - Aug 25
A1: Type of Company | B1: Total Count | E1: Total RSVP Approved | F1: Total Pending | G1: Total Sign Ups | I1: Notable Companies
A2: Game Studio | B2: 143 | E2: 406 | F2: 168 | G2: =E2+F2 -> 574 | I2: Wargaming
A3: Game Publisher | B3: 67 | D3: # increase WoW | E3: =E2-'Data - Aug 13'!F2 -> 119 | F3: =F2-'Data - Aug 13'!G2 -> 20 | G3: =G2-'Data - Aug 13'!H2 -> 139 | I3: Activision
A4: Infrastructure | B4: 66 | D4: % increase WoW | E4: =(E2-'Data - Aug 13'!F2)/'Data - Aug 13'!F2 -> 0.41463415 | F4: =(F2-'Data - Aug 13'!G2)/'Data - Aug 13'!G2 -> 0.13513514 | G4: =(G2-'Data - Aug 13'!H2)/'Data - Aug 13'!H2 -> 0.31954023 | I4: Twitch
A5: Blockchain | B5: 55 | I5: TikTok
A6: Others | B6: 52 | I6: Discord
A7: Media | B7: 40 | I7: Com2Us
A8: AI | B8: 31 | I8: Team Liquid
A9: Games | B9: 31 | I9: Tilting Point
A10: VC | B10: 17 | I10: Gameloft
A11: iGaming | B11: 11 | I11: Griffin Gaming
A12: Wallet | B12: 8 | I12: Ubisoft
A13: Exchange | B13: 1 | I13: Krafton
I14: Carry1st
I15: Wemade / Wemix
I16: Xsolla
I17: Reddit
I18: TapNation
I19: Paramount Global
I20: Disney
I21: Microsoft
I22: Sony
I23: Google
